[2021-10-30 07:06:39,807] {taskinstance.py:1035} INFO - Dependencies all met for <TaskInstance: python_dag.transfrom scheduled__2021-10-29T00:00:00+00:00 [queued]>
[2021-10-30 07:06:39,812] {taskinstance.py:1035} INFO - Dependencies all met for <TaskInstance: python_dag.transfrom scheduled__2021-10-29T00:00:00+00:00 [queued]>
[2021-10-30 07:06:39,813] {taskinstance.py:1241} INFO - 
--------------------------------------------------------------------------------
[2021-10-30 07:06:39,814] {taskinstance.py:1242} INFO - Starting attempt 1 of 1
[2021-10-30 07:06:39,815] {taskinstance.py:1243} INFO - 
--------------------------------------------------------------------------------
[2021-10-30 07:06:39,822] {taskinstance.py:1262} INFO - Executing <Task(_PythonDecoratedOperator): transfrom> on 2021-10-29 00:00:00+00:00
[2021-10-30 07:06:39,825] {standard_task_runner.py:52} INFO - Started process 297 to run task
[2021-10-30 07:06:39,828] {standard_task_runner.py:76} INFO - Running: ['airflow', 'tasks', 'run', 'python_dag', 'transfrom', 'scheduled__2021-10-29T00:00:00+00:00', '--job-id', '10', '--raw', '--subdir', 'DAGS_FOLDER/python_dag.py', '--cfg-path', '/tmp/tmp5l5f9z9q', '--error-file', '/tmp/tmpbo3w3flg']
[2021-10-30 07:06:39,829] {standard_task_runner.py:77} INFO - Job 10: Subtask transfrom
[2021-10-30 07:06:39,848] {logging_mixin.py:109} INFO - Running <TaskInstance: python_dag.transfrom scheduled__2021-10-29T00:00:00+00:00 [running]> on host a7208e2bdec4
[2021-10-30 07:06:39,865] {taskinstance.py:1412} INFO - Exporting the following env vars:
AIRFLOW_CTX_DAG_OWNER=airflow
AIRFLOW_CTX_DAG_ID=python_dag
AIRFLOW_CTX_TASK_ID=transfrom
AIRFLOW_CTX_EXECUTION_DATE=2021-10-29T00:00:00+00:00
AIRFLOW_CTX_DAG_RUN_ID=scheduled__2021-10-29T00:00:00+00:00
[2021-10-30 07:06:39,867] {logging_mixin.py:109} INFO - Transform
[2021-10-30 07:06:39,867] {taskinstance.py:1686} ERROR - Task failed with exception
Traceback (most recent call last):
  File "/usr/local/lib/python3.8/dist-packages/airflow/models/taskinstance.py", line 1324, in _run_raw_task
    self._execute_task_with_callbacks(context)
  File "/usr/local/lib/python3.8/dist-packages/airflow/models/taskinstance.py", line 1443, in _execute_task_with_callbacks
    result = self._execute_task(context, self.task)
  File "/usr/local/lib/python3.8/dist-packages/airflow/models/taskinstance.py", line 1499, in _execute_task
    result = execute_callable(context=context)
  File "/usr/local/lib/python3.8/dist-packages/airflow/decorators/base.py", line 134, in execute
    return_value = super().execute(context)
  File "/usr/local/lib/python3.8/dist-packages/airflow/operators/python.py", line 151, in execute
    return_value = self.execute_callable()
  File "/usr/local/lib/python3.8/dist-packages/airflow/operators/python.py", line 162, in execute_callable
    return self.python_callable(*self.op_args, **self.op_kwargs)
  File "/opt/airflow/dags/python_dag.py", line 18, in transfrom
    return {'data': data + 1}
TypeError: unsupported operand type(s) for +: 'dict' and 'int'
[2021-10-30 07:06:39,872] {taskinstance.py:1270} INFO - Marking task as FAILED. dag_id=python_dag, task_id=transfrom, execution_date=20211029T000000, start_date=20211030T070639, end_date=20211030T070639
[2021-10-30 07:06:39,878] {standard_task_runner.py:88} ERROR - Failed to execute job 10 for task transfrom
Traceback (most recent call last):
  File "/usr/local/lib/python3.8/dist-packages/airflow/task/task_runner/standard_task_runner.py", line 85, in _start_by_fork
    args.func(args, dag=self.dag)
  File "/usr/local/lib/python3.8/dist-packages/airflow/cli/cli_parser.py", line 48, in command
    return func(*args, **kwargs)
  File "/usr/local/lib/python3.8/dist-packages/airflow/utils/cli.py", line 92, in wrapper
    return f(*args, **kwargs)
  File "/usr/local/lib/python3.8/dist-packages/airflow/cli/commands/task_command.py", line 292, in task_run
    _run_task_by_selected_method(args, dag, ti)
  File "/usr/local/lib/python3.8/dist-packages/airflow/cli/commands/task_command.py", line 107, in _run_task_by_selected_method
    _run_raw_task(args, ti)
  File "/usr/local/lib/python3.8/dist-packages/airflow/cli/commands/task_command.py", line 180, in _run_raw_task
    ti._run_raw_task(
  File "/usr/local/lib/python3.8/dist-packages/airflow/utils/session.py", line 70, in wrapper
    return func(*args, session=session, **kwargs)
  File "/usr/local/lib/python3.8/dist-packages/airflow/models/taskinstance.py", line 1324, in _run_raw_task
    self._execute_task_with_callbacks(context)
  File "/usr/local/lib/python3.8/dist-packages/airflow/models/taskinstance.py", line 1443, in _execute_task_with_callbacks
    result = self._execute_task(context, self.task)
  File "/usr/local/lib/python3.8/dist-packages/airflow/models/taskinstance.py", line 1499, in _execute_task
    result = execute_callable(context=context)
  File "/usr/local/lib/python3.8/dist-packages/airflow/decorators/base.py", line 134, in execute
    return_value = super().execute(context)
  File "/usr/local/lib/python3.8/dist-packages/airflow/operators/python.py", line 151, in execute
    return_value = self.execute_callable()
  File "/usr/local/lib/python3.8/dist-packages/airflow/operators/python.py", line 162, in execute_callable
    return self.python_callable(*self.op_args, **self.op_kwargs)
  File "/opt/airflow/dags/python_dag.py", line 18, in transfrom
    return {'data': data + 1}
TypeError: unsupported operand type(s) for +: 'dict' and 'int'
[2021-10-30 07:06:39,924] {local_task_job.py:154} INFO - Task exited with return code 1
[2021-10-30 07:06:39,936] {local_task_job.py:264} INFO - 0 downstream tasks scheduled from follow-on schedule check
[2021-10-30 07:06:40,706] {taskinstance.py:1035} INFO - Dependencies all met for <TaskInstance: python_dag.transfrom manual__2021-10-30T07:06:37.265367+00:00 [queued]>
[2021-10-30 07:06:40,710] {taskinstance.py:1035} INFO - Dependencies all met for <TaskInstance: python_dag.transfrom manual__2021-10-30T07:06:37.265367+00:00 [queued]>
[2021-10-30 07:06:40,711] {taskinstance.py:1241} INFO - 
--------------------------------------------------------------------------------
[2021-10-30 07:06:40,712] {taskinstance.py:1242} INFO - Starting attempt 1 of 1
[2021-10-30 07:06:40,713] {taskinstance.py:1243} INFO - 
--------------------------------------------------------------------------------
[2021-10-30 07:06:40,719] {taskinstance.py:1262} INFO - Executing <Task(_PythonDecoratedOperator): transfrom> on 2021-10-30 07:06:37.265367+00:00
[2021-10-30 07:06:40,722] {standard_task_runner.py:52} INFO - Started process 300 to run task
[2021-10-30 07:06:40,725] {standard_task_runner.py:76} INFO - Running: ['airflow', 'tasks', 'run', 'python_dag', 'transfrom', 'manual__2021-10-30T07:06:37.265367+00:00', '--job-id', '11', '--raw', '--subdir', 'DAGS_FOLDER/python_dag.py', '--cfg-path', '/tmp/tmpp2va9dgb', '--error-file', '/tmp/tmpxiq0o38e']
[2021-10-30 07:06:40,727] {standard_task_runner.py:77} INFO - Job 11: Subtask transfrom
[2021-10-30 07:06:40,744] {logging_mixin.py:109} INFO - Running <TaskInstance: python_dag.transfrom manual__2021-10-30T07:06:37.265367+00:00 [running]> on host a7208e2bdec4
[2021-10-30 07:06:40,763] {taskinstance.py:1412} INFO - Exporting the following env vars:
AIRFLOW_CTX_DAG_OWNER=airflow
AIRFLOW_CTX_DAG_ID=python_dag
AIRFLOW_CTX_TASK_ID=transfrom
AIRFLOW_CTX_EXECUTION_DATE=2021-10-30T07:06:37.265367+00:00
AIRFLOW_CTX_DAG_RUN_ID=manual__2021-10-30T07:06:37.265367+00:00
[2021-10-30 07:06:40,764] {logging_mixin.py:109} INFO - Transform
[2021-10-30 07:06:40,765] {taskinstance.py:1686} ERROR - Task failed with exception
Traceback (most recent call last):
  File "/usr/local/lib/python3.8/dist-packages/airflow/models/taskinstance.py", line 1324, in _run_raw_task
    self._execute_task_with_callbacks(context)
  File "/usr/local/lib/python3.8/dist-packages/airflow/models/taskinstance.py", line 1443, in _execute_task_with_callbacks
    result = self._execute_task(context, self.task)
  File "/usr/local/lib/python3.8/dist-packages/airflow/models/taskinstance.py", line 1499, in _execute_task
    result = execute_callable(context=context)
  File "/usr/local/lib/python3.8/dist-packages/airflow/decorators/base.py", line 134, in execute
    return_value = super().execute(context)
  File "/usr/local/lib/python3.8/dist-packages/airflow/operators/python.py", line 151, in execute
    return_value = self.execute_callable()
  File "/usr/local/lib/python3.8/dist-packages/airflow/operators/python.py", line 162, in execute_callable
    return self.python_callable(*self.op_args, **self.op_kwargs)
  File "/opt/airflow/dags/python_dag.py", line 18, in transfrom
    return {'data': data + 1}
TypeError: unsupported operand type(s) for +: 'dict' and 'int'
[2021-10-30 07:06:40,771] {taskinstance.py:1270} INFO - Marking task as FAILED. dag_id=python_dag, task_id=transfrom, execution_date=20211030T070637, start_date=20211030T070640, end_date=20211030T070640
[2021-10-30 07:06:40,776] {standard_task_runner.py:88} ERROR - Failed to execute job 11 for task transfrom
Traceback (most recent call last):
  File "/usr/local/lib/python3.8/dist-packages/airflow/task/task_runner/standard_task_runner.py", line 85, in _start_by_fork
    args.func(args, dag=self.dag)
  File "/usr/local/lib/python3.8/dist-packages/airflow/cli/cli_parser.py", line 48, in command
    return func(*args, **kwargs)
  File "/usr/local/lib/python3.8/dist-packages/airflow/utils/cli.py", line 92, in wrapper
    return f(*args, **kwargs)
  File "/usr/local/lib/python3.8/dist-packages/airflow/cli/commands/task_command.py", line 292, in task_run
    _run_task_by_selected_method(args, dag, ti)
  File "/usr/local/lib/python3.8/dist-packages/airflow/cli/commands/task_command.py", line 107, in _run_task_by_selected_method
    _run_raw_task(args, ti)
  File "/usr/local/lib/python3.8/dist-packages/airflow/cli/commands/task_command.py", line 180, in _run_raw_task
    ti._run_raw_task(
  File "/usr/local/lib/python3.8/dist-packages/airflow/utils/session.py", line 70, in wrapper
    return func(*args, session=session, **kwargs)
  File "/usr/local/lib/python3.8/dist-packages/airflow/models/taskinstance.py", line 1324, in _run_raw_task
    self._execute_task_with_callbacks(context)
  File "/usr/local/lib/python3.8/dist-packages/airflow/models/taskinstance.py", line 1443, in _execute_task_with_callbacks
    result = self._execute_task(context, self.task)
  File "/usr/local/lib/python3.8/dist-packages/airflow/models/taskinstance.py", line 1499, in _execute_task
    result = execute_callable(context=context)
  File "/usr/local/lib/python3.8/dist-packages/airflow/decorators/base.py", line 134, in execute
    return_value = super().execute(context)
  File "/usr/local/lib/python3.8/dist-packages/airflow/operators/python.py", line 151, in execute
    return_value = self.execute_callable()
  File "/usr/local/lib/python3.8/dist-packages/airflow/operators/python.py", line 162, in execute_callable
    return self.python_callable(*self.op_args, **self.op_kwargs)
  File "/opt/airflow/dags/python_dag.py", line 18, in transfrom
    return {'data': data + 1}
TypeError: unsupported operand type(s) for +: 'dict' and 'int'
[2021-10-30 07:06:40,821] {local_task_job.py:154} INFO - Task exited with return code 1
[2021-10-30 07:06:40,834] {local_task_job.py:264} INFO - 0 downstream tasks scheduled from follow-on schedule check
[2021-10-30 07:24:29,001] {taskinstance.py:1035} INFO - Dependencies all met for <TaskInstance: python_dag.transfrom manual__2021-10-30T07:24:26.715507+00:00 [queued]>
[2021-10-30 07:24:29,004] {taskinstance.py:1035} INFO - Dependencies all met for <TaskInstance: python_dag.transfrom manual__2021-10-30T07:24:26.715507+00:00 [queued]>
[2021-10-30 07:24:29,004] {taskinstance.py:1241} INFO - 
--------------------------------------------------------------------------------
[2021-10-30 07:24:29,005] {taskinstance.py:1242} INFO - Starting attempt 1 of 1
[2021-10-30 07:24:29,006] {taskinstance.py:1243} INFO - 
--------------------------------------------------------------------------------
[2021-10-30 07:24:29,011] {taskinstance.py:1262} INFO - Executing <Task(_PythonDecoratedOperator): transfrom> on 2021-10-30 07:24:26.715507+00:00
[2021-10-30 07:24:29,014] {standard_task_runner.py:52} INFO - Started process 454 to run task
[2021-10-30 07:24:29,015] {standard_task_runner.py:76} INFO - Running: ['airflow', 'tasks', 'run', 'python_dag', 'transfrom', 'manual__2021-10-30T07:24:26.715507+00:00', '--job-id', '13', '--raw', '--subdir', 'DAGS_FOLDER/python_dag.py', '--cfg-path', '/tmp/tmpj23p_cdr', '--error-file', '/tmp/tmp1s3hwitf']
[2021-10-30 07:24:29,017] {standard_task_runner.py:77} INFO - Job 13: Subtask transfrom
[2021-10-30 07:24:29,031] {logging_mixin.py:109} INFO - Running <TaskInstance: python_dag.transfrom manual__2021-10-30T07:24:26.715507+00:00 [running]> on host a7208e2bdec4
[2021-10-30 07:24:29,046] {taskinstance.py:1412} INFO - Exporting the following env vars:
AIRFLOW_CTX_DAG_OWNER=airflow
AIRFLOW_CTX_DAG_ID=python_dag
AIRFLOW_CTX_TASK_ID=transfrom
AIRFLOW_CTX_EXECUTION_DATE=2021-10-30T07:24:26.715507+00:00
AIRFLOW_CTX_DAG_RUN_ID=manual__2021-10-30T07:24:26.715507+00:00
[2021-10-30 07:24:29,047] {logging_mixin.py:109} INFO - <class 'dict'>
[2021-10-30 07:24:29,048] {python.py:152} INFO - Done. Returned value was: {'total_order_value': 1236.7}
[2021-10-30 07:24:29,053] {taskinstance.py:1270} INFO - Marking task as SUCCESS. dag_id=python_dag, task_id=transfrom, execution_date=20211030T072426, start_date=20211030T072429, end_date=20211030T072429
[2021-10-30 07:24:29,071] {local_task_job.py:154} INFO - Task exited with return code 0
[2021-10-30 07:24:29,077] {local_task_job.py:264} INFO - 0 downstream tasks scheduled from follow-on schedule check
